Workbook

Sheet Planungshilfe 1.Sem
A1: Prüfungsplan Klasse 5R1 | Plano das Provas Turma 5R1 | J1: Anzahl SuS | Número alunos: | K1: ausfüllen| preencher
A2: SW | B2: Datum von bis | E2: Montag Segunda | F2: Dienstag Terça | G2: Mittwoch Quarta | H2: Donnerstag Quinta | I2: Freitag Sexta | J2: Samstag Sábado | K2: Bemerkungen
A3: 1 | B3: 46055 | C3: - | D3: =B3+4 -> 46059 | M3: Fach | Lehrkraft | N3: Matéria | Prof.
M4: Raumwunsch | N4: Solicitação Sala
M5: U-Stunden | N5: Horário
A6: =A3+1 -> 2 | B6: =D3+3 -> 46062 | C6: - | D6: =B6+4 -> 46066
M8: Beispiel: | N8: Exemplo:
A9: =A6+1 -> 3 | B9: =D6+3 -> 46069 | C9: - | D9: =B9+4 -> 46073 | K9: Karnevalsferien | Féria de Carnaval | M9: Mat | Sal | N9: Pgram | Jana
M10: Prüfungsraum | N10: Sala de Provas
M11: 2.-3. Std. | N11: 2a e 3a aula
A12: =A9+1 -> 4 | B12: =D9+3 -> 46076 | C12: - | D12: =B12+4 -> 46080
A15: =A12+1 -> 5 | B15: =D12+3 -> 46083 | C15: - | D15: =B15+4 -> 46087 | M15: Raumwunsch
M16: Wird kein Raumwunsch angegeben, bleibt der aktuelle Raum aus dem Stundenplan; falls dies ein Fachraum ist und dies nicht gewünscht ist, dort "Klassenraum" angeben.
A18: =A15+1 -> 6 | B18: =D15+3 -> 46090 | C18: - | D18: =B18+4 -> 46094 | M18: Solicitação Sala
M19: Se nenhuma preferência de sala for indicada, permanecerá a sala atual do horário escolar; caso se trate de uma sala especializada e isso não seja desejado, indique “sala de aula”.
A21: =A18+1 -> 7 | B21: =D18+3 -> 46097 | C21: - | D21: =B21+4 -> 46101
A24: =A21+1 -> 8 | B24: =D21+3 -> 46104 | C24: - | D24: =B24+4 -> 46108 | M24: Nur Segmentleitung: Folgende Termine markieren:
N25: unterrichtsfrei | sem aula
N26: Nachschreibtermine | Segunda Chamada
A27: =A24+1 -> 9 | B27: =D24+3 -> 46111 | C27: - | D27: =B27+4 -> 46115 | K27: Osterferien | Férias de Páscoa | N27: Klassenfahrten | Viagem da Turma
N28: Woche der dt. Sprache | Semana da língua alemã
N29: Schulsamstag | Sábado letivo
A30: =A27+1 -> 10 | B30: =D27+3 -> 46118 | C30: - | D30: =B30+4 -> 46122 | N30: Schriftliches Abitur | Abitur escrito
N31: Mündliches Abitur |Abitur oral
A33: =A30+1 -> 11 | B33: =D30+3 -> 46125 | C33: - | D33: =B33+4 -> 46129
A36: =A33+1 -> 12 | B36: =D33+3 -> 46132 | C36: - | D36: =B36+4 -> 46136 | K36: Feiertage | Feriados
A39: =A36+1 -> 13 | B39: =D36+3 -> 46139 | C39: - | D39: =B39+4 -> 46143
A42: =A39+1 -> 14 | B42: =D39+3 -> 46146 | C42: - | D42: =B42+4 -> 46150
A45: =A42+1 -> 15 | B45: =D42+3 -> 46153 | C45: - | D45: =B45+4 -> 46157
A48: =A45+1 -> 16 | B48: =D45+3 -> 46160 | C48: - | D48: =B48+4 -> 46164
A51: =A48+1 -> 17 | B51: =D48+3 -> 46167 | C51: - | D51: =B51+4 -> 46171
A54: =A51+1 -> 18 | B54: =D51+3 -> 46174 | C54: - | D54: =B54+4 -> 46178 | K54: Feiertage | Feriados
A57: =A54+1 -> 19 | B57: =D54+3 -> 46181 | C57: - | D57: =B57+4 -> 46185
A60: =A57+1 -> 20 | B60: =D57+3 -> 46188 | C60: - | D60: =B60+4 -> 46192
A63: =A60+1 -> 21 | B63: =D60+3 -> 46195 | C63: - | D63: =B63+4 -> 46199
A66: =A63+1 -> 22 | B66: =D63+3 -> 46202 | C66: - | D66: =B66+4 -> 46206
A69: =A66+1 -> 23 | B69: =D66+3 -> 46209 | C69: - | D69: =B69+4 -> 46213

Sheet Planungshilfe 2.Sem
A1: Prüfungsplan Klasse 5R1 | Plano das Provas Turma 5R1 | J1: Anzahl SuS | Número alunos: | K1: ausfüllen| preencher
A2: SW | B2: Datum von bis | E2: Montag Segunda | F2: Dienstag Terça | G2: Mittwoch Quarta | H2: Donnerstag Quinta | I2: Freitag Sexta | J2: Samstag Sábado | K2: Bemerkungen
A3: 1 | B3: 46237 | C3: - | D3: =B3+4 -> 46241 | M3: Fach | Lehrkraft | N3: Matéria | Prof.
M4: Raumwunsch | N4: Solicitação Sala
M5: U-Stunden | N5: Horário
A6: =A3+1 -> 2 | B6: =D3+3 -> 46244 | C6: - | D6: =B6+4 -> 46248
M8: Beispiel: | N8: Exemplo:
A9: =A6+1 -> 3 | B9: =D6+3 -> 46251 | C9: - | D9: =B9+4 -> 46255 | M9: Mat | Sal | N9: Pgram | Jana
M10: Prüfungsraum | N10: Sala de Provas
M11: 2.-3. Std. | N11: 2a e 3a aula
A12: =A9+1 -> 4 | B12: =D9+3 -> 46258 | C12: - | D12: =B12+4 -> 46262
A15: =A12+1 -> 5 | B15: =D12+3 -> 46265 | C15: - | D15: =B15+4 -> 46269 | M15: Raumwunsch
M16: Wird kein Raumwunsch angegeben, bleibt der aktuelle Raum aus dem Stundenplan; falls dies ein Fachraum ist und dies nicht gewünscht ist, dort "Klassenraum" angeben.
A18: =A15+1 -> 6 | B18: =D15+3 -> 46272 | C18: - | D18: =B18+4 -> 46276 | K18: Feiertag | Feriado | M18: Solicitação Sala
M19: Se nenhuma preferência de sala for indicada, permanecerá a sala atual do horário escolar; caso se trate de uma sala especializada e isso não seja desejado, indique “sala de aula”.
A21: =A18+1 -> 7 | B21: =D18+3 -> 46279 | C21: - | D21: =B21+4 -> 46283
A24: =A21+1 -> 8 | B24: =D21+3 -> 46286 | C24: - | D24: =B24+4 -> 46290 | M24: Nur Segmentleitung: Folgende Termine markieren:
N25: unterrichtsfrei | sem aula
N26: Nachschreibtermine | Segunda Chamada
A27: =A24+1 -> 9 | B27: =D24+3 -> 46293 | C27: - | D27: =B27+4 -> 46297 | N27: Klassenfahrten | Viagem da Turma
N28: Woche der dt. Sprache | Semana da língua alemã
N29: Schulsamstag | Sábado letivo
A30: =A27+1 -> 10 | B30: =D27+3 -> 46300 | C30: - | D30: =B30+4 -> 46304 | N30: Schriftliches Abitur | Abitur escrito
N31: Mündliches Abitur |Abitur oral
A33: =A30+1 -> 11 | B33: =D30+3 -> 46307 | C33: - | D33: =B33+4 -> 46311 | K33: Kartoffelferien | Férias das batatas
A36: =A33+1 -> 12 | B36: =D33+3 -> 46314 | C36: - | D36: =B36+4 -> 46318
A39: =A36+1 -> 13 | B39: =D36+3 -> 46321 | C39: - | D39: =B39+4 -> 46325
A42: =A39+1 -> 14 | B42: =D39+3 -> 46328 | C42: - | D42: =B42+4 -> 46332 | K42: Feiertag | Feriado
A45: =A42+1 -> 15 | B45: =D42+3 -> 46335 | C45: - | D45: =B45+4 -> 46339
A48: =A45+1 -> 16 | B48: =D45+3 -> 46342 | C48: - | D48: =B48+4 -> 46346 | K48: Feiertag | Feriado
A51: =A48+1 -> 17 | B51: =D48+3 -> 46349 | C51: - | D51: =B51+4 -> 46353
A54: =A51+1 -> 18 | B54: =D51+3 -> 46356 | C54: - | D54: =B54+4 -> 46360
A57: =A54+1 -> 19 | B57: =D54+3 -> 46363 | C57: - | D57: =B57+4 -> 46367
A60: =A57+1 -> 20 | B60: =D57+3 -> 46370 | C60: - | D60: =B60+4 -> 46374

Sheet 9C1
A1: Prüfungsplan Klasse 9C1 | Plano das Provas Turma 9C1 | J1: Anzahl SuS | Número alunos: 19
A2: SW | B2: Datum von bis | E2: Montag Segunda | F2: Dienstag Terça | G2: Mittwoch Quarta | H2: Donnerstag Quinta | I2: Freitag Sexta | J2: Samstag Sábado
A3: 1 | B3: 46055 | C3: - | D3: =B3+4 -> 46059 | L3: Fach | Lehrkraft | M3: Matéria | Prof.
L4: Raumwunsch | M4: Solicitação Sala
L5: U-Stunden | M5: Horário
A6: =A3+1 -> 2 | B6: =D3+3 -> 46062 | C6: - | D6: =B6+4 -> 46066
L8: Beispiel: | M8: Exemplo:
A9: =A6+1 -> 3 | B9: =D6+3 -> 46069 | C9: - | D9: =B9+4 -> 46073 | E9: unterrichtsfrei sem aula | F9: unterrichtsfrei sem aula | G9: unterrichtsfrei sem aula | H9: unterrichtsfrei sem aula | I9: unterrichtsfrei sem aula | L9: Mat | Sal | M9: Pgram | Jana
L10: Prüfungsraum | M10: Sala de Provas
L11: 2.-3. Std. | M11: 2a e 3a aula
A12: =A9+1 -> 4 | B12: =D9+3 -> 46076 | C12: - | D12: =B12+4 -> 46080
A15: =A12+1 -> 5 | B15: =D12+3 -> 46083 | C15: - | D15: =B15+4 -> 46087
A18: =A15+1 -> 6 | B18: =D15+3 -> 46090 | C18: - | D18: =B18+4 -> 46094
A21: =A18+1 -> 7 | B21: =D18+3 -> 46097 | C21: - | D21: =B21+4 -> 46101 | J21: SÁBADO LETIVO
A24: =A21+1 -> 8 | B24: =D21+3 -> 46104 | C24: - | D24: =B24+4 -> 46108 | L24: Nur Segmentleitung: Folgende Termine markieren:
M25: unterrichtsfrei | sem aula
M26: Nachschreibtermine | Segunda Chamada
A27: =A24+1 -> 9 | B27: =D24+3 -> 46111 | C27: - | D27: =B27+4 -> 46115 | E27: Pred - Raf | F27: BIO / ALE | G27: GL | H27: unterrichtsfrei sem aula | I27: unterrichtsfrei sem aula | M27: Klassenfahrten | Viagem da Turma
E28: Sala de prova | F28: 8º e 9º tempo | G28: 6 Tempo | M28: Woche der dt. Sprache | Semana da língua alemã
E29: 1o e 2o tempos | F29: Sala de provas | G29: sala de aula | M29: Schulsamstag | Sábado letivo
A30: =A27+1 -> 10 | B30: =D27+3 -> 46118 | C30: - | D30: =B30+4 -> 46122 | M30: Evitar a marcação de provas
A33: =A30+1 -> 11 | B33: =D30+3 -> 46125 | C33: - | D33: =B33+4 -> 46129 | E33: HIS / JuLa | G33: PORT/JANA | I33: ING / Apa-Pah-Velo | L33: DATAS IMPORTANTES
E34: 6,7 TEMPOS | G34: 4 E 5 TEMPOS | I34: 2 e 3 tempos | L34: 13.05 | M34: AR
E35: SALA DE PROVAS | G35: SALA DE PROVAS | I35: A 301 e A 304 | L35: 27.04 | M35: LANÇAMENTO DE NOTAS NO PORTAL
A36: =A33+1 -> 12 | B36: =D33+3 -> 46132 | C36: - | D36: =B36+4 -> 46136 | E36: GEO | F36: unterrichtsfrei sem aula | H36: unterrichtsfrei sem aula
E37: 2o e 3o tempos
E38: Sala de aula
A39: =A36+1 -> 13 | B39: =D36+3 -> 46139 | C39: - | D39: =B39+4 -> 46143 | F39: DAF | Caro - SGa - EFr | I39: unterrichtsfrei sem aula
F40: A-304
F41: 4.5
A42: =A39+1 -> 14 | B42: =D39+3 -> 46146 | C42: - | D42: =B42+4 -> 46150 | G42: MATEMÁTICA | J42: 2CH
G43: Sala de provas
G44: 4° e 5° tempos
A45: =A42+1 -> 15 | B45: =D42+3 -> 46153 | C45: - | D45: =B45+4 -> 46157 | F45: BIO / ALE | G45: QUI/FAB | J45: AR | L45: ASSEMBLÉIA COM OS REPRESENTANTES
F46: 8º e 9º tempo | G46: 2º tempo
F47: Sala de provas | G47: SALA DE PROVAS
A48: =A45+1 -> 16 | B48: =D45+3 -> 46160 | C48: - | D48: =B48+4 -> 46164 | E48: Pred - Raf | I48: GEO
E49: Sala de prova | I49: 2o e 3o tempos
E50: 1o e 2o tempos | I50: Sala de aula
A51: =A48+1 -> 17 | B51: =D48+3 -> 46167 | C51: - | D51: =B51+4 -> 46171 | E51: GL | G51: PORT/JANA
...

Sheet 9C2
A1: Prüfungsplan Klasse 9C2 | Plano das Provas Turma 9C2 | J1: Anzahl SuS | Número alunos:19
A2: SW | B2: Datum von bis | E2: Montag Segunda | F2: Dienstag Terça | G2: Mittwoch Quarta | H2: Donnerstag Quinta | I2: Freitag Sexta | J2: Samstag Sábado
A3: 1 | B3: 46055 | C3: - | D3: =B3+4 -> 46059 | L3: Fach | Lehrkraft | M3: Matéria | Prof.
L4: Raumwunsch | M4: Solicitação Sala
L5: U-Stunden | M5: Horário
A6: =A3+1 -> 2 | B6: =D3+3 -> 46062 | C6: - | D6: =B6+4 -> 46066
L8: Beispiel: | M8: Exemplo:
A9: =A6+1 -> 3 | B9: =D6+3 -> 46069 | C9: - | D9: =B9+4 -> 46073 | E9: unterrichtsfrei sem aula | F9: unterrichtsfrei sem aula | G9: unterrichtsfrei sem aula | H9: unterrichtsfrei sem aula | I9: unterrichtsfrei sem aula | L9: Mat | Sal | M9: Pgram | Jana
L10: Prüfungsraum | M10: Sala de Provas
L11: 2.-3. Std. | M11: 2a e 3a aula
A12: =A9+1 -> 4 | B12: =D9+3 -> 46076 | C12: - | D12: =B12+4 -> 46080
A15: =A12+1 -> 5 | B15: =D12+3 -> 46083 | C15: - | D15: =B15+4 -> 46087
A18: =A15+1 -> 6 | B18: =D15+3 -> 46090 | C18: - | D18: =B18+4 -> 46094
A21: =A18+1 -> 7 | B21: =D18+3 -> 46097 | C21: - | D21: =B21+4 -> 46101 | J21: SÁBADO LETIVO
A24: =A21+1 -> 8 | B24: =D21+3 -> 46104 | C24: - | D24: =B24+4 -> 46108 | L24: Nur Segmentleitung: Folgende Termine markieren:
M25: unterrichtsfrei | sem aula
M26: Nachschreibtermine | Segunda Chamada
A27: =A24+1 -> 9 | B27: =D24+3 -> 46111 | C27: - | D27: =B27+4 -> 46115 | E27: Pred - Raf | F27: BIO / ALE | H27: unterrichtsfrei sem aula | I27: unterrichtsfrei sem aula | M27: Klassenfahrten | Viagem da Turma
E28: Sala de prova | F28: 8º e 9º tempo | G28: GL 6.tempo | M28: Woche der dt. Sprache | Semana da língua alemã
E29: 1o e 2o tempos | F29: Sala de provas | G29: sala de aula | M29: Schulsamstag | Sábado letivo
A30: =A27+1 -> 10 | B30: =D27+3 -> 46118 | C30: - | D30: =B30+4 -> 46122 | M30: Evitar a marcação de provas
A33: =A30+1 -> 11 | B33: =D30+3 -> 46125 | C33: - | D33: =B33+4 -> 46129 | E33: HIS / JuLa | G33: PORT/JANA | I33: ING / Apa-Pah-Velo | L33: DATAS IMPORTANTES
E34: 6.7 | G34: 4 E 5 TEMPOS | I34: 2 e 3 tempos | L34: 13.05 | M34: AR
E35: SALA DE PROVAS | G35: SALA DE PROVAS | I35: A 301 e A 304 | L35: 27.04 | M35: LANÇAMENTO DE NOTAS NO PORTAL
A36: =A33+1 -> 12 | B36: =D33+3 -> 46132 | C36: - | D36: =B36+4 -> 46136 | E36: GEO | F36: unterrichtsfrei sem aula | H36: unterrichtsfrei sem aula
E37: 2o e 3o tempos
E38: Sala de aula
A39: =A36+1 -> 13 | B39: =D36+3 -> 46139 | C39: - | D39: =B39+4 -> 46143 | F39: DAF | Caro - SGa - EFr | I39: unterrichtsfrei sem aula
F40: A-304
F41: 4.5
A42: =A39+1 -> 14 | B42: =D39+3 -> 46146 | C42: - | D42: =B42+4 -> 46150 | G42: MATEMÁTICA | J42: 2CH
G43: Sala de provas
G44: 4° e 5° tempos
A45: =A42+1 -> 15 | B45: =D42+3 -> 46153 | C45: - | D45: =B45+4 -> 46157 | F45: BIO / ALE | G45: QUI/FAB | J45: AR | L45: ASSEMBLÉIA COM OS REPRESENTANTES
F46: 8º e 9º tempo | G46: 2º tempo
F47: Sala de provas | G47: SALA DE PROVAS
A48: =A45+1 -> 16 | B48: =D45+3 -> 46160 | C48: - | D48: =B48+4 -> 46164 | E48: Pred - Raf | I48: GEO
E49: Sala de prova | I49: 2o e 3o tempos
E50: 1o e 2o tempos | I50: Sala de aula
A51: =A48+1 -> 17 | B51: =D48+3 -> 46167 | C51: - | D51: =B51+4 -> 46171 | E51: GL | G51: PORT/JANA
...

Sheet 10C1
A1: Prüfungsplan Klasse 10C1 | Plano das Provas Turma 10C1 | J1: Anzahl SuS | Número alunos:18
A2: SW | B2: Datum von bis | E2: Montag Segunda | F2: Dienstag Terça | G2: Mittwoch Quarta | H2: Donnerstag Quinta | I2: Freitag Sexta | J2: Samstag Sábado
A3: 1 | B3: 46055 | C3: - | D3: =B3+4 -> 46059 | E3: Fach | Lehrkraft | F3: Matéria | Prof. | L3: Fach | Lehrkraft | M3: Matéria | Prof.
E4: Raumwunsch | F4: Solicitação Sala | L4: Raumwunsch | M4: Solicitação Sala
E5: U-Stunden | F5: Horário | L5: U-Stunden | M5: Horário
A6: =A3+1 -> 2 | B6: =D3+3 -> 46062 | C6: - | D6: =B6+4 -> 46066
L8: Beispiel: | M8: Exemplo:
A9: =A6+1 -> 3 | B9: =D6+3 -> 46069 | C9: - | D9: =B9+4 -> 46073 | E9: unterrichtsfrei sem aula | F9: unterrichtsfrei sem aula | G9: unterrichtsfrei sem aula | H9: unterrichtsfrei sem aula | I9: unterrichtsfrei sem aula | L9: Mat | Sal | M9: Pgram | Jana
L10: Prüfungsraum | M10: Sala de Provas
L11: 2.-3. Std. | M11: 2a e 3a aula
A12: =A9+1 -> 4 | B12: =D9+3 -> 46076 | C12: - | D12: =B12+4 -> 46080
A15: =A12+1 -> 5 | B15: =D12+3 -> 46083 | C15: - | D15: =B15+4 -> 46087
A18: =A15+1 -> 6 | B18: =D15+3 -> 46090 | C18: - | D18: =B18+4 -> 46094
A21: =A18+1 -> 7 | B21: =D18+3 -> 46097 | C21: - | D21: =B21+4 -> 46101
A24: =A21+1 -> 8 | B24: =D21+3 -> 46104 | C24: - | D24: =B24+4 -> 46108 | I24: Bio (Lza) | L24: Nur Segmentleitung: Folgende Termine markieren:
I25: Sala de provas | M25: unterrichtsfrei | sem aula
I26: 6º e 7º tempos | M26: Nachschreibtermine | Segunda Chamada
A27: =A24+1 -> 9 | B27: =D24+3 -> 46111 | C27: - | D27: =B27+4 -> 46115 | E27: Port (SMo/MFo/BPad) | H27: unterrichtsfrei sem aula | I27: unterrichtsfrei sem aula | M27: Klassenfahrten | Viagem da Turma
E28: Sala de provas | M28: Woche der dt. Sprache | Semana da língua alemã
E29: 4º, 5 e 6º tempos | M29: Schulsamstag | Sábado letivo
A30: =A27+1 -> 10 | B30: =D27+3 -> 46118 | C30: - | D30: =B30+4 -> 46122 | F30: Hist. (ALu) - 10º e 11º tempos - Sala de Provas | G30: GL | I30: Geografia | M30: Schriftliches Abitur | Abitur escrito
G31: 3° tempo | I31: Rios | M31: Mündliches Abitur |Abitur oral
G32: Car - KrK - EFr | I32: 2.3
A33: =A30+1 -> 11 | B33: =D30+3 -> 46125 | C33: - | D33: =B33+4 -> 46129 | E33: QUÍMICA | H33: Ing | APA | I33: DaF | L33: DATAS IMPORTANTES
E34: 4º e 5º tempos | H34: E301 | I34: 2° e 3° tempo | L34: 13.05 | M34: AR
E35: Sala de provas | H35: 2ª e 3ª aulas | I35: Eth - Krk - EFr | L35: 27.04 | M35: LANÇAMENTO DE NOTAS NO PORTAL
A36: =A33+1 -> 12 | B36: =D33+3 -> 46132 | C36: - | D36: =B36+4 -> 46136 | E36: QUÍMICA | F36: unterrichtsfrei sem aula | H36: unterrichtsfrei sem aula
E37: 4º e 5º tempos
E38: Sala de provas
A39: =A36+1 -> 13 | B39: =D36+3 -> 46139 | C39: - | D39: =B39+4 -> 46143 | E39: FIS | VSI | F39: MATEMÁTICA | I39: unterrichtsfrei sem aula
E40: Sala de provas | F40: Sala de Provas
E41: 3° e 4° tempos | F41: 6° e 7° tempos
A42: =A39+1 -> 14 | B42: =D39+3 -> 46146 | C42: - | D42: =B42+4 -> 46150 | F42: p[[+ | G42: SOC (Kle) | J42: 2CH
G43: 4o tempo
G44: E301
A45: =A42+1 -> 15 | B45: =D42+3 -> 46153 | C45: - | D45: =B45+4 -> 46157 | G45: Geografia
G46: Rios
G47: 06+
A48: =A45+1 -> 16 | B48: =D45+3 -> 46160 | C48: - | D48: =B48+4 -> 46164 | E48: Port (SMo/MFo/BPad) | G48: AG1-10 | I48: Filosofia (Lan) - | J48: AG1-10
E49: Sala de provas | I49: 1º e 2º tempos
...

Sheet 10C2
A1: Prüfungsplan Klasse 10C2 | Plano das Provas Turma 10C2 | J1: Anzahl SuS | Número alunos:19
A2: SW | B2: Datum von bis | E2: Montag Segunda | F2: Dienstag Terça | G2: Mittwoch Quarta | H2: Donnerstag Quinta | I2: Freitag Sexta | J2: Samstag Sábado
A3: 1 | B3: 46055 | C3: - | D3: =B3+4 -> 46059 | E3: Fach | Lehrkraft | F3: Matéria | Prof. | L3: Fach | Lehrkraft | M3: Matéria | Prof.
E4: Raumwunsch | F4: Solicitação Sala | L4: Raumwunsch | M4: Solicitação Sala
E5: U-Stunden | F5: Horário | L5: U-Stunden | M5: Horário
A6: =A3+1 -> 2 | B6: =D3+3 -> 46062 | C6: - | D6: =B6+4 -> 46066
L8: Beispiel: | M8: Exemplo:
A9: =A6+1 -> 3 | B9: =D6+3 -> 46069 | C9: - | D9: =B9+4 -> 46073 | E9: unterrichtsfrei sem aula | F9: unterrichtsfrei sem aula | G9: unterrichtsfrei sem aula | H9: unterrichtsfrei sem aula | I9: unterrichtsfrei sem aula | L9: Mat | Sal | M9: Pgram | Jana
L10: Prüfungsraum | M10: Sala de Provas
L11: 2.-3. Std. | M11: 2a e 3a aula
A12: =A9+1 -> 4 | B12: =D9+3 -> 46076 | C12: - | D12: =B12+4 -> 46080
A15: =A12+1 -> 5 | B15: =D12+3 -> 46083 | C15: - | D15: =B15+4 -> 46087
A18: =A15+1 -> 6 | B18: =D15+3 -> 46090 | C18: - | D18: =B18+4 -> 46094
A21: =A18+1 -> 7 | B21: =D18+3 -> 46097 | C21: - | D21: =B21+4 -> 46101
A24: =A21+1 -> 8 | B24: =D21+3 -> 46104 | C24: - | D24: =B24+4 -> 46108 | I24: Bio (Lza) | L24: Nur Segmentleitung: Folgende Termine markieren:
I25: Sala de provas | M25: unterrichtsfrei | sem aula
I26: 6º e 7º tempos | M26: Nachschreibtermine | Segunda Chamada
A27: =A24+1 -> 9 | B27: =D24+3 -> 46111 | C27: - | D27: =B27+4 -> 46115 | E27: Port (SMo/MFo/BPad) | H27: unterrichtsfrei sem aula | I27: unterrichtsfrei sem aula | M27: Klassenfahrten | Viagem da Turma
E28: Sala de provas | M28: Woche der dt. Sprache | Semana da língua alemã
E29: 4º, 5 e 6º tempos | M29: Schulsamstag | Sábado letivo
A30: =A27+1 -> 10 | B30: =D27+3 -> 46118 | C30: - | D30: =B30+4 -> 46122 | F30: Hist. (ALu) - 10º e 11º tempos - Sala de Provas | G30: GL | I30: Geografia | M30: Schriftliches Abitur | Abitur escrito
G31: 3° tempo | I31: Rios | M31: Mündliches Abitur |Abitur oral
G32: Car - KrK - EFr | I32: 3.4
A33: =A30+1 -> 11 | B33: =D30+3 -> 46125 | C33: - | D33: =B33+4 -> 46129 | E33: QUÍMICA | G33: Ing | Vir | I33: DaF | L33: DATAS IMPORTANTES
E34: 4º e 5º tempos | G34: E306 | I34: 2° e 3° sala de aula | L34: 13.05 | M34: AR
E35: Sala de provas | G35: 4a e 5ª aulas | I35: Eth - Krk - EFr | L35: 27.04 | M35: LANÇAMENTO DE NOTAS NO PORTAL
A36: =A33+1 -> 12 | B36: =D33+3 -> 46132 | C36: - | D36: =B36+4 -> 46136 | E36: QUÍMICA | F36: unterrichtsfrei sem aula | H36: unterrichtsfrei sem aula
E37: 4º e 5º tempos
E38: Sala de provas
A39: =A36+1 -> 13 | B39: =D36+3 -> 46139 | C39: - | D39: =B39+4 -> 46143 | E39: FIS | VSI | F39: MATEMÁTICA | I39: unterrichtsfrei sem aula
E40: Sala de provas | F40: Sala de Provas
E41: 3° e 4° tempos | F41: 6° e 7° tempos
A42: =A39+1 -> 14 | B42: =D39+3 -> 46146 | C42: - | D42: =B42+4 -> 46150 | G42: SOC (Kle) | J42: 2CH
G43: 4o tempo
G44: E301
A45: =A42+1 -> 15 | B45: =D42+3 -> 46153 | C45: - | D45: =B45+4 -> 46157 | G45: Geografia
G46: Rios
G47: 6,7 BRU,RIO,KLE SALA DE PROVAS
A48: =A45+1 -> 16 | B48: =D45+3 -> 46160 | C48: - | D48: =B48+4 -> 46164 | E48: Port (SMo/MFo/BPad) | G48: AG1-10 | I48: Filosofia (Lan) -
E49: Sala de provas | I49: 1º e 2º tempos
...

Sheet 11C1
A1: Prüfungsplan Klasse 11C1 | Plano das Provas Turma 11C1 | J1: Anzahl SuS | Número alunos:22
A2: SW | B2: Datum von bis | E2: Montag Segunda | F2: Dienstag Terça | G2: Mittwoch Quarta | H2: Donnerstag Quinta | I2: Freitag Sexta | J2: Samstag Sábado
A3: 1 | B3: 46055 | C3: - | D3: =B3+4 -> 46059 | E3: Fach | Lehrkraft | F3: Matéria | Prof. | L3: Fach | Lehrkraft | M3: Matéria | Prof.
E4: Raumwunsch | F4: Solicitação Sala | L4: Raumwunsch | M4: Solicitação Sala
E5: U-Stunden | F5: Horário | L5: U-Stunden | M5: Horário
A6: =A3+1 -> 2 | B6: =D3+3 -> 46062 | C6: - | D6: =B6+4 -> 46066
L8: Beispiel: | M8: Exemplo:
A9: =A6+1 -> 3 | B9: =D6+3 -> 46069 | C9: - | D9: =B9+4 -> 46073 | E9: unterrichtsfrei sem aula | F9: unterrichtsfrei sem aula | G9: unterrichtsfrei sem aula | H9: unterrichtsfrei sem aula | I9: unterrichtsfrei sem aula | L9: Mat | Sal | M9: Pgram | Jana
L10: Prüfungsraum | M10: Sala de Provas
L11: 2.-3. Std. | M11: 2a e 3a aula
A12: =A9+1 -> 4 | B12: =D9+3 -> 46076 | C12: - | D12: =B12+4 -> 46080
A15: =A12+1 -> 5 | B15: =D12+3 -> 46083 | C15: - | D15: =B15+4 -> 46087
A18: =A15+1 -> 6 | B18: =D15+3 -> 46090 | C18: - | D18: =B18+4 -> 46094 | E18: S1-11 BRE SALA DE PROVAS 1-7 | F18: S1-11 BRE SALA DE PROVAS 1-7
A21: =A18+1 -> 7 | B21: =D18+3 -> 46097 | C21: - | D21: =B21+4 -> 46101
A24: =A21+1 -> 8 | B24: =D21+3 -> 46104 | C24: - | D24: =B24+4 -> 46108 | H24: FIS/CADU | L24: Nur Segmentleitung: Folgende Termine markieren:
H25: 1º e 2º tempos | M25: unterrichtsfrei | sem aula
H26: A314 | M26: Nachschreibtermine | Segunda Chamada
A27: =A24+1 -> 9 | B27: =D24+3 -> 46111 | C27: - | D27: =B27+4 -> 46115 | E27: ING/BEA | F27: DaF/SGa/KrK/CBu | H27: unterrichtsfrei sem aula | I27: unterrichtsfrei sem aula | M27: Klassenfahrten | Viagem da Turma
E28: A314 | F28: 4º e 5º tempos | M28: Woche der dt. Sprache | Semana da língua alemã
E29: 6º e 7º tempos | F29: Sala de provas | M29: Schulsamstag | Sábado letivo
A30: =A27+1 -> 10 | B30: =D27+3 -> 46118 | C30: - | D30: =B30+4 -> 46122 | E30: GL/SGa/KrK/CBu | G30: MAT/ClaMe e JJ | M30: Schriftliches Abitur | Abitur escrito
E31: 5º tempo | G31: 9° e 10° tempos | M31: Mündliches Abitur |Abitur oral
E32: A304/A314/A308 | G32: Sala de provas
A33: =A30+1 -> 11 | B33: =D30+3 -> 46125 | C33: - | D33: =B33+4 -> 46129 | F33: BIO / ALE | G33: Hist/Ver | H33: LP/LIT/RED - Raf/AMu/ACo
F34: 9º e 10º tempo | G34: sala de provas | H34: Sala de provas
F35: Sala de provas | G35: primeiro e segundo tempos | H35: 4º, 5º e 6º tempos | L35: DATAS IMPORTANTES
A36: =A33+1 -> 12 | B36: =D33+3 -> 46132 | C36: - | D36: =B36+4 -> 46136 | E36: GEO | F36: unterrichtsfrei sem aula | H36: unterrichtsfrei sem aula | L36: 13.05 | M36: AR
E37: 2o e 3o tempos | L37: 27.04 | M37: LANÇAMENTO DE NOTAS NO PORTAL
E38: Sala de aula
A39: =A36+1 -> 13 | B39: =D36+3 -> 46139 | C39: - | D39: =B39+4 -> 46143 | E39: QUÍMICA | I39: unterrichtsfrei sem aula
E40: 1º e 2º tempos
E41: Sala de Provas
A42: =A39+1 -> 14 | B42: =D39+3 -> 46146 | C42: - | D42: =B42+4 -> 46150 | J42: 2CH
A45: =A42+1 -> 15 | B45: =D42+3 -> 46153 | C45: - | D45: =B45+4 -> 46157 | G45: Filosofia (Lan) | H45: FIS/CADU | I45: GEO | L45: ASSEMBLÉIA COM OS REPRESENTANTES
G46: 9º e 10 tempos | H46: 1º e 2º tempos | I46: 4.5
G47: sala de Provas | H47: A314 | I47: Sala de aula
A48: =A45+1 -> 16 | B48: =D45+3 -> 46160 | C48: - | D48: =B48+4 -> 46164 | E48: GL/SGa/KrK/CBu | F48: DaF/SGa/KrK/CBu | I48: SOC (Kle)
E49: 5º tempo | F49: 4º e 5º tempos | I49: 2o tempo
E50: A304/A314/A308 | F50: Sala de provas | I50: A314
A51: =A48+1 -> 17 | B51: =D48+3 -> 46167 | C51: - | D51: =B51+4 -> 46171 | F51: MAT/ClaMe e JJ | G51: Hist/Ver
...

Sheet 11C2
A1: Prüfungsplan Klasse 11C2 | Plano das Provas Turma 11C2 | J1: Anzahl SuS | Número alunos:17
A2: SW | B2: Datum von bis | E2: Montag Segunda | F2: Dienstag Terça | G2: Mittwoch Quarta | H2: Donnerstag Quinta | I2: Freitag Sexta | J2: Samstag Sábado
A3: 1 | B3: 46055 | C3: - | D3: =B3+4 -> 46059 | E3: Fach | Lehrkraft | F3: Matéria | Prof. | L3: Fach | Lehrkraft | M3: Matéria | Prof.
E4: Raumwunsch | F4: Solicitação Sala | L4: Raumwunsch | M4: Solicitação Sala
E5: U-Stunden | F5: Horário | L5: U-Stunden | M5: Horário
A6: =A3+1 -> 2 | B6: =D3+3 -> 46062 | C6: - | D6: =B6+4 -> 46066
L8: Beispiel: | M8: Exemplo:
A9: =A6+1 -> 3 | B9: =D6+3 -> 46069 | C9: - | D9: =B9+4 -> 46073 | E9: unterrichtsfrei sem aula | F9: unterrichtsfrei sem aula | G9: unterrichtsfrei sem aula | H9: unterrichtsfrei sem aula | I9: unterrichtsfrei sem aula | L9: Mat | Sal | M9: Pgram | Jana
L10: Prüfungsraum | M10: Sala de Provas
L11: 2.-3. Std. | M11: 2a e 3a aula
A12: =A9+1 -> 4 | B12: =D9+3 -> 46076 | C12: - | D12: =B12+4 -> 46080
A15: =A12+1 -> 5 | B15: =D12+3 -> 46083 | C15: - | D15: =B15+4 -> 46087 | L15: Nur Segmentleitung: Folgende Termine markieren:
M16: unterrichtsfrei | sem aula
M17: Nachschreibtermine | Segunda Chamada
A18: =A15+1 -> 6 | B18: =D15+3 -> 46090 | C18: - | D18: =B18+4 -> 46094 | E18: S1-11 BRE SALA DE PROVAS 1-7 | F18: S1-11 BRE SALA DE PROVAS 1-7 | M18: Klassenfahrten | Viagem da Turma
M19: Woche der dt. Sprache | Semana da língua alemã
M20: Schulsamstag | Sábado letivo
A21: =A18+1 -> 7 | B21: =D18+3 -> 46097 | C21: - | D21: =B21+4 -> 46101 | M21: Schriftliches Abitur | Abitur escrito
M22: Mündliches Abitur |Abitur oral
A24: =A21+1 -> 8 | B24: =D21+3 -> 46104 | C24: - | D24: =B24+4 -> 46108 | H24: FIS/CADU | I24: ING
H25: 4º e 5º tempos | I25: Pah | L25: ='11C1'!L35 -> DATAS IMPORTANTES
H26: A308 | I26: 6 e 7 tempos / A308 | L26: ='11C1'!L36 -> 13.05 | M26: ='11C1'!M36 -> AR
A27: =A24+1 -> 9 | B27: =D24+3 -> 46111 | C27: - | D27: =B27+4 -> 46115 | F27: DaF/SGa/KrK/CBu | H27: unterrichtsfrei sem aula | I27: unterrichtsfrei sem aula | L27: ='11C1'!L37 -> 27.04 | M27: ='11C1'!M37 -> LANÇAMENTO DE NOTAS NO PORTAL
F28: 4º e 5º tempos
F29: Sala de provas
A30: =A27+1 -> 10 | B30: =D27+3 -> 46118 | C30: - | D30: =B30+4 -> 46122 | E30: GL/SGa/KrK/CBu | G30: MAT/ClaMe e JJ
E31: 5º tempo | G31: 9° e 10° tempos
E32: A304/A314/A308 | G32: Sala de provas
A33: =A30+1 -> 11 | B33: =D30+3 -> 46125 | C33: - | D33: =B33+4 -> 46129 | F33: BIO / ALE | G33: Hist/Ver | H33: LP/LIT/RED - Raf/AMu/ACo
F34: 9º e 10º tempo | G34: sala de provas | H34: Sala de provas
F35: Sala de provas | G35: primeiro e segundo | H35: 4º, 5º e 6º tempos
A36: =A33+1 -> 12 | B36: =D33+3 -> 46132 | C36: - | D36: =B36+4 -> 46136 | E36: GEO | F36: unterrichtsfrei sem aula | H36: unterrichtsfrei sem aula
E37: 2o e 3o tempos
E38: Sala de aula
A39: =A36+1 -> 13 | B39: =D36+3 -> 46139 | C39: - | D39: =B39+4 -> 46143 | E39: QUÍMICA | I39: unterrichtsfrei sem aula
E40: 1º e 2º tempos
E41: Sala de Provas
A42: =A39+1 -> 14 | B42: =D39+3 -> 46146 | C42: - | D42: =B42+4 -> 46150 | J42: 2CH
A45: =A42+1 -> 15 | B45: =D42+3 -> 46153 | C45: - | D45: =B45+4 -> 46157 | G45: Filosofia (Lan) | H45: FIS/CADU | I45: GEO | L45: ASSEMBLÉIA COM OS REPRESENTANTES
G46: 9º e 10 tempos | H46: 4º e 5º tempos | I46: 4.5
...

Sheet 12C1
A1: Prüfungsplan Klasse 12C1 | Plano das Provas Turma 12C1 | J1: Anzahl SuS | Número alunos:18
A2: SW | B2: Datum von bis | E2: Montag Segunda | F2: Dienstag Terça | G2: Mittwoch Quarta | H2: Donnerstag Quinta | I2: Freitag Sexta | J2: Samstag Sábado
A3: 1 | B3: 46055 | C3: - | D3: =B3+4 -> 46059 | E3: Fach | Lehrkraft | F3: Matéria | Prof. | L3: Fach | Lehrkraft | M3: Matéria | Prof.
E4: Raumwunsch | F4: Solicitação Sala | L4: Raumwunsch | M4: Solicitação Sala
E5: U-Stunden | F5: Horário | L5: U-Stunden | M5: Horário
A6: =A3+1 -> 2 | B6: =D3+3 -> 46062 | C6: - | D6: =B6+4 -> 46066
L8: Beispiel: | M8: Exemplo:
A9: =A6+1 -> 3 | B9: =D6+3 -> 46069 | C9: - | D9: =B9+4 -> 46073 | E9: unterrichtsfrei sem aula | F9: unterrichtsfrei sem aula | G9: unterrichtsfrei sem aula | H9: unterrichtsfrei sem aula | I9: unterrichtsfrei sem aula | L9: Mat | Sal | M9: Pgram | Jana
L10: Prüfungsraum | M10: Sala de Provas
L11: 2.-3. Std. | M11: 2a e 3a aula
A12: =A9+1 -> 4 | B12: =D9+3 -> 46076 | C12: - | D12: =B12+4 -> 46080
L14: Nur Segmentleitung: Folgende Termine markieren:
A15: =A12+1 -> 5 | B15: =D12+3 -> 46083 | C15: - | D15: =B15+4 -> 46087 | M15: unterrichtsfrei | sem aula
M16: Nachschreibtermine | Segunda Chamada
M17: Klassenfahrten | Viagem da Turma
A18: =A15+1 -> 6 | B18: =D15+3 -> 46090 | C18: - | D18: =B18+4 -> 46094 | M18: Woche der dt. Sprache | Semana da língua alemã
M19: Schulsamstag | Sábado letivo
M20: Schriftliches Abitur | Abitur escrito
A21: =A18+1 -> 7 | B21: =D18+3 -> 46097 | C21: - | D21: =B21+4 -> 46101 | M21: Mündliches Abitur |Abitur oral
L23: ='11C2'!L25 -> DATAS IMPORTANTES
A24: =A21+1 -> 8 | B24: =D21+3 -> 46104 | C24: - | D24: =B24+4 -> 46108 | H24: S1-12 BRE SALA DE PROVAS 1-7 | I24: S1-12 BRE SALA DE PROVAS 1-7 | L24: ='11C2'!L26 -> 13.05 | M24: ='11C2'!M26 -> AR
L25: ='11C2'!L27 -> 27.04 | M25: ='11C2'!M27 -> LANÇAMENTO DE NOTAS NO PORTAL
A27: =A24+1 -> 9 | B27: =D24+3 -> 46111 | C27: - | D27: =B27+4 -> 46115 | E27: ING | F27: BIO / ALE | H27: unterrichtsfrei sem aula | I27: unterrichtsfrei sem aula
E28: Pah 1 e 2 tempos - A 312 | F28: 2º e 3º tempos Sala de Provas
A29: =A27+1 -> 10 | B29: =D27+3 -> 46118 | C29: - | D29: =B29+4 -> 46122 | F29: FIS/CADU | I29: Port (Deb e Amu)
F30: 9º e 10º tempos | I30: Sala de provas
F31: Sala de provas | I31: 3º, 4º e 5º tempos
A32: =A29+1 -> 11 | B32: =D29+3 -> 46125 | C32: - | D32: =B32+4 -> 46129 | G32: HIS/Wag | I32: DaF
G33: 10º e 11º tempos | I33: 6° e 7° tempo
G34: Sala de provas | I34: Eth - CBu - EFr
A35: =A32+1 -> 12 | B35: =D32+3 -> 46132 | C35: - | D35: =B35+4 -> 46136 | F35: unterrichtsfrei sem aula | H35: unterrichtsfrei sem aula | I35: GEO
I36: 2o e 3o tempos
I37: Sala de aula
A38: =A35+1 -> 13 | B38: =D35+3 -> 46139 | C38: - | D38: =B38+4 -> 46143 | F38: QUIMICA | H38: MAT | I38: unterrichtsfrei sem aula
F39: 9º e 10º tempos | H39: 4,5 TEMPOS
F40: Sala de provas | H40: SALA DE PROVAS
A41: =A38+1 -> 14 | B41: =D38+3 -> 46146 | C41: - | D41: =B41+4 -> 46150 | F41: GL | J41: 2CH
F42: 6° tempo
F43: Eth - CBu - EFr
A44: =A41+1 -> 15 | B44: =D41+3 -> 46153 | C44: - | D44: =B44+4 -> 46157 | H44: S2-12 BRE SALA DE PROVAS 1-7 | I44: S2-12 BRE SALA DE PROVAS 1-7 | L44: UERJ:15.05
...

Sheet 12C2
A1: Prüfungsplan Klasse 12C2 | Plano das Provas Turma 12C2 | J1: Anzahl SuS | Número alunos:16
A2: SW | B2: Datum von bis | E2: Montag Segunda | F2: Dienstag Terça | G2: Mittwoch Quarta | H2: Donnerstag Quinta | I2: Freitag Sexta | J2: Samstag Sábado
A3: 1 | B3: 46055 | C3: - | D3: =B3+4 -> 46059 | E3: Fach | Lehrkraft | F3: Matéria | Prof. | L3: Fach | Lehrkraft | M3: Matéria | Prof.
E4: Raumwunsch | F4: Solicitação Sala | L4: Raumwunsch | M4: Solicitação Sala
E5: U-Stunden | F5: Horário | L5: U-Stunden | M5: Horário
A6: =A3+1 -> 2 | B6: =D3+3 -> 46062 | C6: - | D6: =B6+4 -> 46066
L8: Beispiel: | M8: Exemplo:
A9: =A6+1 -> 3 | B9: =D6+3 -> 46069 | C9: - | D9: =B9+4 -> 46073 | E9: unterrichtsfrei sem aula | F9: unterrichtsfrei sem aula | G9: unterrichtsfrei sem aula | H9: unterrichtsfrei sem aula | I9: unterrichtsfrei sem aula | J9: unterrichtsfrei sem aula | L9: Mat | Sal | M9: Pgram | Jana
L10: Prüfungsraum | M10: Sala de Provas
L11: 2.-3. Std. | M11: 2a e 3a aula
A12: =A9+1 -> 4 | B12: =D9+3 -> 46076 | C12: - | D12: =B12+4 -> 46080
A15: =A12+1 -> 5 | B15: =D12+3 -> 46083 | C15: - | D15: =B15+4 -> 46087
A18: =A15+1 -> 6 | B18: =D15+3 -> 46090 | C18: - | D18: =B18+4 -> 46094
A21: =A18+1 -> 7 | B21: =D18+3 -> 46097 | C21: - | D21: =B21+4 -> 46101
A24: =A21+1 -> 8 | B24: =D21+3 -> 46104 | C24: - | D24: =B24+4 -> 46108 | H24: S1-12 BRE SALA DE PROVAS 1-7 | I24: S1-12 BRE SALA DE PROVAS 1-7 | L24: Nur Segmentleitung: Folgende Termine markieren:
M25: unterrichtsfrei | sem aula
M26: Nachschreibtermine | Segunda Chamada
A27: =A24+1 -> 9 | B27: =D24+3 -> 46111 | C27: - | D27: =B27+4 -> 46115 | E27: ING | F27: BIO / ALE | H27: unterrichtsfrei sem aula | I27: unterrichtsfrei sem aula | M27: Klassenfahrten | Viagem da Turma
E28: Isb | F28: 2º e 3º tempos | M28: Woche der dt. Sprache | Semana da língua alemã
E29: 5º e 6º tempos A305 | F29: Sala de provas | M29: Schulsamstag | Sábado letivo
A30: =A27+1 -> 10 | B30: =D27+3 -> 46118 | C30: - | D30: =B30+4 -> 46122 | F30: FIS/CADU | I30: Port (Deb e Amu) | M30: Schriftliches Abitur | Abitur escrito
F31: 9º e 10º tempos | I31: Sala de provas | M31: Mündliches Abitur |Abitur oral
F32: Sala de provas | I32: 3º, 4º e 5º tempos
A33: =A30+1 -> 11 | B33: =D30+3 -> 46125 | C33: - | D33: =B33+4 -> 46129 | G33: HIS/Wag | I33: DaF | L33: ='12C1'!L23 -> DATAS IMPORTANTES
G34: 10º e 11º tempos | I34: 6° e 7° tempo | L34: ='12C1'!L24 -> 13.05 | M34: ='12C1'!M24 -> AR
G35: Sala de provas | I35: Eth - CBu - EFr | L35: ='12C1'!L25 -> 27.04 | M35: ='12C1'!M25 -> LANÇAMENTO DE NOTAS NO PORTAL
A36: =A33+1 -> 12 | B36: =D33+3 -> 46132 | C36: - | D36: =B36+4 -> 46136 | F36: unterrichtsfrei sem aula | H36: unterrichtsfrei sem aula | I36: GEO
I37: 2o e 3o tempos
I38: Sala de aula
A39: =A36+1 -> 13 | B39: =D36+3 -> 46139 | C39: - | D39: =B39+4 -> 46143 | F39: QUÍMICA | H39: MAT | I39: unterrichtsfrei sem aula
F40: 9º e 10º tempos | H40: 4,5 TEMPOS
F41: Sala de provas | H41: SALA DE PROVAS
A42: =A39+1 -> 14 | B42: =D39+3 -> 46146 | C42: - | D42: =B42+4 -> 46150 | F42: GL | J42: 2CH
F43: 6° tempo
F44: Eth - CBu - EFr
A45: =A42+1 -> 15 | B45: =D42+3 -> 46153 | C45: - | D45: =B45+4 -> 46157 | H45: S2-12 BRE SALA DE PROVAS 1-7 | I45: S2-12 BRE SALA DE PROVAS 1-7 | L45: UERJ:15.05
A48: =A45+1 -> 16 | B48: =D45+3 -> 46160 | C48: - | D48: =B48+4 -> 46164 | F48: Geo Apro(zeca) | G48: SOC (Kle) | I48: Filosofia (Lan) | L48: UERJ:22.05
F49: 4,5 tempo | G49: 6o tempo | I49: 1º e 2º tempos
F50: Sala de provas | G50: A305 | I50: Sala de Provas
A51: =A48+1 -> 17 | B51: =D48+3 -> 46167 | C51: - | D51: =B51+4 -> 46171 | F51: BIO / ALE | I51: Port (Deb e Amu) | L51: UERJ:30.05
...

Sheet Tabelle1
